Workbook

Sheet Portfolio & Rebalancing
A1: 🦅 DYNASTIE-DEPOT – Rebalancing Tool v4.0
A2: =TODAY() -> 46188
A4: Position | B4: Ticker | C4: Typ | D4: Broker | E4: US- Faktor | F4: Depotwert € | G4: Ist- Anteil % | H4: Ziel- Anteil % | I4: Zielwert € | J4: Fehlbetrag € | K4: Abw. % | L4: Aktion | M4: ⚠️ Cap- Check | N4: DEFCON Score | O4: 🚩 FLAG-Status | P4: 💶 Sparrate €/Monat | Q4: Gewicht | R4: 🛒 Nachkauf- Signal
A5: EUWAX Gold | B5: EWG2 | C5: Gold | D5: Scalable | E5: 0 | F5: 654 | G5: =IF(F$29=0,0,F5/F$29) -> 0.040149425 | H5: =VLOOKUP($B5,'Parameter & Regeln'!$A$56:$B$62,2,FALSE)/'Parameter & Regeln'!$B$4 -> 0.049466537 | I5: =H5*F$29 -> 805.76785 | J5: =I5-F5 -> 151.76785 | K5: =G5-H5 -> -0.0093171127 | L5: =IF(C5="Aktie",IF(K5>'Parameter & Regeln'!B$9,"📉 Reduzieren",IF(K5<-'Parameter & Regeln'!B$9,"📈 Aufstocken","⚖️ Halten")),IF(K5>'Parameter & Regeln'!B$8,"📉 Reduzieren",IF(K5<-'Parameter & Regeln'!B$8,"📈 Aufstocken","⚖️ Halten"))) -> ⚖️ Halten | M5: =IF(C5="Aktie",IF(G5>'Parameter & Regeln'!B$10,"🚨 ÜBER CAP","✅ OK"),"") | P5: =IF(C5="Aktie",'Parameter & Regeln'!$B$4*'Parameter & Regeln'!$B$6*Q5/SUMIFS($Q$5:$Q$24,$C$5:$C$24,"Aktie"),IFERROR(VLOOKUP(B5,'Parameter & Regeln'!$A$56:$B$62,2,FALSE),0)) -> 51 | Q5: =IF(OR(C5="ETF",C5="Gold"),H5,IF(C5<>"Aktie",0,IF(OR(LEFT(O5,1)="🔴",LEFT(N5,8)="DEFCON 1"),0,IF(LEFT(N5,8)="DEFCON 2",IFERROR(VLOOKUP(B5,'Parameter & Regeln'!$A$41:$C$53,3,FALSE),0)*'Parameter & Regeln'!$B$27,IFERROR(VLOOKUP(B5,'Parameter & Regeln'!$A$41:$C$53,3,FALSE),0))))) -> 0.049466537 | R5: =IF(AND(C5="Aktie",OR(LEFT(O5,1)="🔴",LEFT(N5,8)="DEFCON 1")),IF(J5>'Parameter & Regeln'!$B$65,"🚩 FLAG (gesperrt)",""),IF(J5>'Parameter & Regeln'!$B$65,"🛒 Nachkaufen",IF(J5<-'Parameter & Regeln'!$B$65,"⏸️ Über Ziel","")))
A6: iShares Core MSCI World | B6: IWDA | C6: ETF | D6: ING | E6: 0.7 | F6: 3943.46 | G6: =IF(F$29=0,0,F6/F$29) -> 0.24209121 | H6: =VLOOKUP($B6,'Parameter & Regeln'!$A$56:$B$62,2,FALSE)/'Parameter & Regeln'!$B$4 -> 0.19980601 | I6: =H6*F$29 -> 3254.6701 | J6: =I6-F6 -> -688.78987 | K6: =G6-H6 -> 0.042285194 | L6: =IF(C6="Aktie",IF(K6>'Parameter & Regeln'!B$9,"📉 Reduzieren",IF(K6<-'Parameter & Regeln'!B$9,"📈 Aufstocken","⚖️ Halten")),IF(K6>'Parameter & Regeln'!B$8,"📉 Reduzieren",IF(K6<-'Parameter & Regeln'!B$8,"📈 Aufstocken","⚖️ Halten"))) -> 📉 Reduzieren | M6: =IF(C6="Aktie",IF(G6>'Parameter & Regeln'!B$10,"🚨 ÜBER CAP","✅ OK"),"") | P6: =IF(C6="Aktie",'Parameter & Regeln'!$B$4*'Parameter & Regeln'!$B$6*Q6/SUMIFS($Q$5:$Q$24,$C$5:$C$24,"Aktie"),IFERROR(VLOOKUP(B6,'Parameter & Regeln'!$A$56:$B$62,2,FALSE),0)) -> 206 | Q6: =IF(OR(C6="ETF",C6="Gold"),H6,IF(C6<>"Aktie",0,IF(OR(LEFT(O6,1)="🔴",LEFT(N6,8)="DEFCON 1"),0,IF(LEFT(N6,8)="DEFCON 2",IFERROR(VLOOKUP(B6,'Parameter & Regeln'!$A$41:$C$53,3,FALSE),0)*'Parameter & Regeln'!$B$27,IFERROR(VLOOKUP(B6,'Parameter & Regeln'!$A$41:$C$53,3,FALSE),0))))) -> 0.19980601 | R6: =IF(AND(C6="Aktie",OR(LEFT(O6,1)="🔴",LEFT(N6,8)="DEFCON 1")),IF(J6>'Parameter & Regeln'!$B$65,"🚩 FLAG (gesperrt)",""),IF(J6>'Parameter & Regeln'!$B$65,"🛒 Nachkaufen",IF(J6<-'Parameter & Regeln'!$B$65,"⏸️ Über Ziel",""))) -> ⏸️ Über Ziel
A7: iShares Core MSCI EM IMI | B7: EIMI | C7: ETF | D7: ING | E7: 0 | F7: 1349.52 | G7: =IF(F$29=0,0,F7/F$29) -> 0.082847785 | H7: =VLOOKUP($B7,'Parameter & Regeln'!$A$56:$B$62,2,FALSE)/'Parameter & Regeln'!$B$4 -> 0.11930165 | I7: =H7*F$29 -> 1943.3225 | J7: =I7-F7 -> 593.80245 | K7: =G7-H7 -> -0.036453864 | L7: =IF(C7="Aktie",IF(K7>'Parameter & Regeln'!B$9,"📉 Reduzieren",IF(K7<-'Parameter & Regeln'!B$9,"📈 Aufstocken","⚖️ Halten")),IF(K7>'Parameter & Regeln'!B$8,"📉 Reduzieren",IF(K7<-'Parameter & Regeln'!B$8,"📈 Aufstocken","⚖️ Halten"))) -> 📈 Aufstocken | M7: =IF(C7="Aktie",IF(G7>'Parameter & Regeln'!B$10,"🚨 ÜBER CAP","✅ OK"),"") | P7: =IF(C7="Aktie",'Parameter & Regeln'!$B$4*'Parameter & Regeln'!$B$6*Q7/SUMIFS($Q$5:$Q$24,$C$5:$C$24,"Aktie"),IFERROR(VLOOKUP(B7,'Parameter & Regeln'!$A$56:$B$62,2,FALSE),0)) -> 123 | Q7: =IF(OR(C7="ETF",C7="Gold"),H7,IF(C7<>"Aktie",0,IF(OR(LEFT(O7,1)="🔴",LEFT(N7,8)="DEFCON 1"),0,IF(LEFT(N7,8)="DEFCON 2",IFERROR(VLOOKUP(B7,'Parameter & Regeln'!$A$41:$C$53,3,FALSE),0)*'Parameter & Regeln'!$B$27,IFERROR(VLOOKUP(B7,'Parameter & Regeln'!$A$41:$C$53,3,FALSE),0))))) -> 0.11930165 | R7: =IF(AND(C7="Aktie",OR(LEFT(O7,1)="🔴",LEFT(N7,8)="DEFCON 1")),IF(J7>'Parameter & Regeln'!$B$65,"🚩 FLAG (gesperrt)",""),IF(J7>'Parameter & Regeln'!$B$65,"🛒 Nachkaufen",IF(J7<-'Parameter & Regeln'!$B$65,"⏸️ Über Ziel",""))) -> 🛒 Nachkaufen
A8: Xtrackers MSCI World ex USA | B8: EXUS | C8: ETF | D8: ING | E8: 0 | F8: 1978.17 | G8: =IF(F$29=0,0,F8/F$29) -> 0.12144096 | H8: =VLOOKUP($B8,'Parameter & Regeln'!$A$56:$B$62,2,FALSE)/'Parameter & Regeln'!$B$4 -> 0.079534433 | I8: =H8*F$29 -> 1295.5483 | J8: =I8-F8 -> -682.6217 | K8: =G8-H8 -> 0.041906527 | L8: =IF(C8="Aktie",IF(K8>'Parameter & Regeln'!B$9,"📉 Reduzieren",IF(K8<-'Parameter & Regeln'!B$9,"📈 Aufstocken","⚖️ Halten")),IF(K8>'Parameter & Regeln'!B$8,"📉 Reduzieren",IF(K8<-'Parameter & Regeln'!B$8,"📈 Aufstocken","⚖️ Halten"))) -> 📉 Reduzieren | M8: =IF(C8="Aktie",IF(G8>'Parameter & Regeln'!B$10,"🚨 ÜBER CAP","✅ OK"),"") | P8: =IF(C8="Aktie",'Parameter & Regeln'!$B$4*'Parameter & Regeln'!$B$6*Q8/SUMIFS($Q$5:$Q$24,$C$5:$C$24,"Aktie"),IFERROR(VLOOKUP(B8,'Parameter & Regeln'!$A$56:$B$62,2,FALSE),0)) -> 82 | Q8: =IF(OR(C8="ETF",C8="Gold"),H8,IF(C8<>"Aktie",0,IF(OR(LEFT(O8,1)="🔴",LEFT(N8,8)="DEFCON 1"),0,IF(LEFT(N8,8)="DEFCON 2",IFERROR(VLOOKUP(B8,'Parameter & Regeln'!$A$41:$C$53,3,FALSE),0)*'Parameter & Regeln'!$B$27,IFERROR(VLOOKUP(B8,'Parameter & Regeln'!$A$41:$C$53,3,FALSE),0))))) -> 0.079534433 | R8: =IF(AND(C8="Aktie",OR(LEFT(O8,1)="🔴",LEFT(N8,8)="DEFCON 1")),IF(J8>'Parameter & Regeln'!$B$65,"🚩 FLAG (gesperrt)",""),IF(J8>'Parameter & Regeln'!$B$65,"🛒 Nachkaufen",IF(J8<-'Parameter & Regeln'!$B$65,"⏸️ Über Ziel",""))) -> ⏸️ Über Ziel
A9: Avantis Global Small Cap Value | B9: AVGC | C9: ETF | D9: Scalable | E9: 0.67 | F9: 1366 | G9: =IF(F$29=0,0,F9/F$29) -> 0.083859502 | H9: =VLOOKUP($B9,'Parameter & Regeln'!$A$56:$B$62,2,FALSE)/'Parameter & Regeln'!$B$4 -> 0.079534433 | I9: =H9*F$29 -> 1295.5483 | J9: =I9-F9 -> -70.451697 | K9: =G9-H9 -> 0.004325069 | L9: =IF(C9="Aktie",IF(K9>'Parameter & Regeln'!B$9,"📉 Reduzieren",IF(K9<-'Parameter & Regeln'!B$9,"📈 Aufstocken","⚖️ Halten")),IF(K9>'Parameter & Regeln'!B$8,"📉 Reduzieren",IF(K9<-'Parameter & Regeln'!B$8,"📈 Aufstocken","⚖️ Halten"))) -> ⚖️ Halten | M9: =IF(C9="Aktie",IF(G9>'Parameter & Regeln'!B$10,"🚨 ÜBER CAP","✅ OK"),"") | P9: =IF(C9="Aktie",'Parameter & Regeln'!$B$4*'Parameter & Regeln'!$B$6*Q9/SUMIFS($Q$5:$Q$24,$C$5:$C$24,"Aktie"),IFERROR(VLOOKUP(B9,'Parameter & Regeln'!$A$56:$B$62,2,FALSE),0)) -> 82 | Q9: =IF(OR(C9="ETF",C9="Gold"),H9,IF(C9<>"Aktie",0,IF(OR(LEFT(O9,1)="🔴",LEFT(N9,8)="DEFCON 1"),0,IF(LEFT(N9,8)="DEFCON 2",IFERROR(VLOOKUP(B9,'Parameter & Regeln'!$A$41:$C$53,3,FALSE),0)*'Parameter & Regeln'!$B$27,IFERROR(VLOOKUP(B9,'Parameter & Regeln'!$A$41:$C$53,3,FALSE),0))))) -> 0.079534433 | R9: =IF(AND(C9="Aktie",OR(LEFT(O9,1)="🔴",LEFT(N9,8)="DEFCON 1")),IF(J9>'Parameter & Regeln'!$B$65,"🚩 FLAG (gesperrt)",""),IF(J9>'Parameter & Regeln'!$B$65,"🛒 Nachkaufen",IF(J9<-'Parameter & Regeln'!$B$65,"⏸️ Über Ziel","")))
A10: VanEck Space Innovators | B10: JEDI | C10: ETF | D10: Scalable | E10: 0.62 | F10: 0 | G10: =IF(F$29=0,0,F10/F$29) -> 0 | H10: =VLOOKUP($B10,'Parameter & Regeln'!$A$56:$B$62,2,FALSE)/'Parameter & Regeln'!$B$4 -> 0.069835112 | I10: =H10*F$29 -> 1137.5546 | J10: =I10-F10 -> 1137.5546 | K10: =G10-H10 -> -0.069835112 | L10: =IF(C10="Aktie",IF(K10>'Parameter & Regeln'!B$9,"📉 Reduzieren",IF(K10<-'Parameter & Regeln'!B$9,"📈 Aufstocken","⚖️ Halten")),IF(K10>'Parameter & Regeln'!B$8,"📉 Reduzieren",IF(K10<-'Parameter & Regeln'!B$8,"📈 Aufstocken","⚖️ Halten"))) -> 📈 Aufstocken | M10: =IF(C10="Aktie",IF(G10>'Parameter & Regeln'!B$10,"🚨 ÜBER CAP","✅ OK"),"") | P10: =IF(C10="Aktie",'Parameter & Regeln'!$B$4*'Parameter & Regeln'!$B$6*Q10/SUMIFS($Q$5:$Q$24,$C$5:$C$24,"Aktie"),IFERROR(VLOOKUP(B10,'Parameter & Regeln'!$A$56:$B$62,2,FALSE),0)) -> 72 | Q10: =IF(OR(C10="ETF",C10="Gold"),H10,IF(C10<>"Aktie",0,IF(OR(LEFT(O10,1)="🔴",LEFT(N10,8)="DEFCON 1"),0,IF(LEFT(N10,8)="DEFCON 2",IFERROR(VLOOKUP(B10,'Parameter & Regeln'!$A$41:$C$53,3,FALSE),0)*'Parameter & Regeln'!$B$27,IFERROR(VLOOKUP(B10,'Parameter & Regeln'!$A$41:$C$53,3,FALSE),0))))) -> 0.069835112 | R10: =IF(AND(C10="Aktie",OR(LEFT(O10,1)="🔴",LEFT(N10,8)="DEFCON 1")),IF(J10>'Parameter & Regeln'!$B$65,"🚩 FLAG (gesperrt)",""),IF(J10>'Parameter & Regeln'!$B$65,"🛒 Nachkaufen",IF(J10<-'Parameter & Regeln'!$B$65,"⏸️ Über Ziel",""))) -> 🛒 Nachkaufen
A11: WisdomTree Quantum Computing | B11: WQTM | C11: ETF | D11: Scalable | E11: 0.68 | F11: 193 | G11: =IF(F$29=0,0,F11/F$29) -> 0.011848378 | H11: =VLOOKUP($B11,'Parameter & Regeln'!$A$56:$B$62,2,FALSE)/'Parameter & Regeln'!$B$4 -> 0.049466537 | I11: =H11*F$29 -> 805.76785 | J11: =I11-F11 -> 612.76785 | K11: =G11-H11 -> -0.03761816 | L11: =IF(C11="Aktie",IF(K11>'Parameter & Regeln'!B$9,"📉 Reduzieren",IF(K11<-'Parameter & Regeln'!B$9,"📈 Aufstocken","⚖️ Halten")),IF(K11>'Parameter & Regeln'!B$8,"📉 Reduzieren",IF(K11<-'Parameter & Regeln'!B$8,"📈 Aufstocken","⚖️ Halten"))) -> 📈 Aufstocken | M11: =IF(C11="Aktie",IF(G11>'Parameter & Regeln'!B$10,"🚨 ÜBER CAP","✅ OK"),"") | P11: =IF(C11="Aktie",'Parameter & Regeln'!$B$4*'Parameter & Regeln'!$B$6*Q11/SUMIFS($Q$5:$Q$24,$C$5:$C$24,"Aktie"),IFERROR(VLOOKUP(B11,'Parameter & Regeln'!$A$56:$B$62,2,FALSE),0)) -> 51 | Q11: =IF(OR(C11="ETF",C11="Gold"),H11,IF(C11<>"Aktie",0,IF(OR(LEFT(O11,1)="🔴",LEFT(N11,8)="DEFCON 1"),0,IF(LEFT(N11,8)="DEFCON 2",IFERROR(VLOOKUP(B11,'Parameter & Regeln'!$A$41:$C$53,3,FALSE),0)*'Parameter & Regeln'!$B$27,IFERROR(VLOOKUP(B11,'Parameter & Regeln'!$A$41:$C$53,3,FALSE),0))))) -> 0.049466537 | R11: =IF(AND(C11="Aktie",OR(LEFT(O11,1)="🔴",LEFT(N11,8)="DEFCON 1")),IF(J11>'Parameter & Regeln'!$B$65,"🚩 FLAG (gesperrt)",""),IF(J11>'Parameter & Regeln'!$B$65,"🛒 Nachkaufen",IF(J11<-'Parameter & Regeln'!$B$65,"⏸️ Über Ziel",""))) -> 🛒 Nachkaufen
A12: Amazon.com | B12: AMZN | C12: Aktie | D12: Scalable | E12: 1 | F12: 381 | G12: =IF(F$29=0,0,F12/F$29) -> 0.023389802 | H12: ='Parameter & Regeln'!$B$35/'Parameter & Regeln'!$B$4 -> 0.038797284 | I12: =H12*F$29 -> 631.97478 | J12: =I12-F12 -> 250.97478 | K12: =G12-H12 -> -0.015407482 | L12: =IF(C12="Aktie",IF(K12>'Parameter & Regeln'!B$9,"📉 Reduzieren",IF(K12<-'Parameter & Regeln'!B$9,"📈 Aufstocken","⚖️ Halten")),IF(K12>'Parameter & Regeln'!B$8,"📉 Reduzieren",IF(K12<-'Parameter & Regeln'!B$8,"📈 Aufstocken","⚖️ Halten"))) -> ⚖️ Halten | M12: =IF(C12="Aktie",IF(G12>'Parameter & Regeln'!B$10,"🚨 ÜBER CAP","✅ OK"),"") -> ✅ OK | N12: DEFCON 1 (42) | O12: 🔴 FLAG: CapEx/OCF TTM 99,2% (15.05.) | P12: =IF(C12="Aktie",'Parameter & Regeln'!$B$4*'Parameter & Regeln'!$B$6*Q12/SUMIFS($Q$5:$Q$24,$C$5:$C$24,"Aktie"),IFERROR(VLOOKUP(B12,'Parameter & Regeln'!$A$56:$B$62,2,FALSE),0)) -> 0 | Q12: =IF(OR(C12="ETF",C12="Gold"),H12,IF(C12<>"Aktie",0,IF(OR(LEFT(O12,1)="🔴",LEFT(N12,8)="DEFCON 1"),0,IF(LEFT(N12,8)="DEFCON 2",IFERROR(VLOOKUP(B12,'Parameter & Regeln'!$A$41:$C$53,3,FALSE),0)*'Parameter & Regeln'!$B$27,IFERROR(VLOOKUP(B12,'Parameter & Regeln'!$A$41:$C$53,3,FALSE),0))))) -> 0 | R12: =IF(AND(C12="Aktie",OR(LEFT(O12,1)="🔴",LEFT(N12,8)="DEFCON 1")),IF(J12>'Parameter & Regeln'!$B$65,"🚩 FLAG (gesperrt)",""),IF(J12>'Parameter & Regeln'!$B$65,"🛒 Nachkaufen",IF(J12<-'Parameter & Regeln'!$B$65,"⏸️ Über Ziel","")))
A13: Amphenol | B13: APH | C13: Aktie | D13: Scalable | E13: 1 | F13: 378 | G13: =IF(F$29=0,0,F13/F$29) -> 0.023205631 | H13: ='Parameter & Regeln'!$B$37/'Parameter & Regeln'!$B$4 -> 0.017458778 | I13: =H13*F$29 -> 284.38865 | J13: =I13-F13 -> -93.611348 | K13: =G13-H13 -> 0.0057468529 | L13: =IF(C13="Aktie",IF(K13>'Parameter & Regeln'!B$9,"📉 Reduzieren",IF(K13<-'Parameter & Regeln'!B$9,"📈 Aufstocken","⚖️ Halten")),IF(K13>'Parameter & Regeln'!B$8,"📉 Reduzieren",IF(K13<-'Parameter & Regeln'!B$8,"📈 Aufstocken","⚖️ Halten"))) -> ⚖️ Halten | M13: =IF(C13="Aktie",IF(G13>'Parameter & Regeln'!B$10,"🚨 ÜBER CAP","✅ OK"),"") -> ✅ OK | N13: DEFCON 2 (61) | O13: 🔴 FLAG: Score 61 (DEFCON 2, Q1 FY26 Tag-+1 Vollanalyse 30.04.) | CommScope-NL 1,6x | China-Tax-ETR 27% strukturell | P13: =IF(C13="Aktie",'Parameter & Regeln'!$B$4*'Parameter & Regeln'!$B$6*Q13/SUMIFS($Q$5:$Q$24,$C$5:$C$24,"Aktie"),IFERROR(VLOOKUP(B13,'Parameter & Regeln'!$A$56:$B$62,2,FALSE),0)) -> 0 | Q13: =IF(OR(C13="ETF",C13="Gold"),H13,IF(C13<>"Aktie",0,IF(OR(LEFT(O13,1)="🔴",LEFT(N13,8)="DEFCON 1"),0,IF(LEFT(N13,8)="DEFCON 2",IFERROR(VLOOKUP(B13,'Parameter & Regeln'!$A$41:$C$53,3,FALSE),0)*'Parameter & Regeln'!$B$27,IFERROR(VLOOKUP(B13,'Parameter & Regeln'!$A$41:$C$53,3,FALSE),0))))) -> 0 | R13: =IF(AND(C13="Aktie",OR(LEFT(O13,1)="🔴",LEFT(N13,8)="DEFCON 1")),IF(J13>'Parameter & Regeln'!$B$65,"🚩 FLAG (gesperrt)",""),IF(J13>'Parameter & Regeln'!$B$65,"🛒 Nachkaufen",IF(J13<-'Parameter & Regeln'!$B$65,"⏸️ Über Ziel","")))
A14: ASML Holding | B14: ASML | C14: Aktie | D14: Scalable | E14: 0 | F14: 560 | G14: =IF(F$29=0,0,F14/F$29) -> 0.034378712 | H14: ='Parameter & Regeln'!$B$36/'Parameter & Regeln'!$B$4 -> 0.031037827 | I14: =H14*F$29 -> 505.57983 | J14: =I14-F14 -> -54.420175 | K14: =G14-H14 -> 0.0033408849 | L14: =IF(C14="Aktie",IF(K14>'Parameter & Regeln'!B$9,"📉 Reduzieren",IF(K14<-'Parameter & Regeln'!B$9,"📈 Aufstocken","⚖️ Halten")),IF(K14>'Parameter & Regeln'!B$8,"📉 Reduzieren",IF(K14<-'Parameter & Regeln'!B$8,"📈 Aufstocken","⚖️ Halten"))) -> ⚖️ Halten | M14: =IF(C14="Aktie",IF(G14>'Parameter & Regeln'!B$10,"🚨 ÜBER CAP","✅ OK"),"") -> ✅ OK | N14: DEFCON 3 (68) | O14: 🟡 DEFCON 3 (68) | China Rev 14.7% Risk-Map | P14: =IF(C14="Aktie",'Parameter & Regeln'!$B$4*'Parameter & Regeln'!$B$6*Q14/SUMIFS($Q$5:$Q$24,$C$5:$C$24,"Aktie"),IFERROR(VLOOKUP(B14,'Parameter & Regeln'!$A$56:$B$62,2,FALSE),0)) -> 55.457981 | Q14: =IF(OR(C14="ETF",C14="Gold"),H14,IF(C14<>"Aktie",0,IF(OR(LEFT(O14,1)="🔴",LEFT(N14,8)="DEFCON 1"),0,IF(LEFT(N14,8)="DEFCON 2",IFERROR(VLOOKUP(B14,'Parameter & Regeln'!$A$41:$C$53,3,FALSE),0)*'Parameter & Regeln'!$B$27,IFERROR(VLOOKUP(B14,'Parameter & Regeln'!$A$41:$C$53,3,FALSE),0))))) -> 32 | R14: =IF(AND(C14="Aktie",OR(LEFT(O14,1)="🔴",LEFT(N14,8)="DEFCON 1")),IF(J14>'Parameter & Regeln'!$B$65,"🚩 FLAG (gesperrt)",""),IF(J14>'Parameter & Regeln'!$B$65,"🛒 Nachkaufen",IF(J14<-'Parameter & Regeln'!$B$65,"⏸️ Über Ziel","")))
A15: Berkshire Hathaway | B15: BRK.B | C15: Aktie | D15: Scalable | E15: 1 | F15: 453 | G15: =IF(F$29=0,0,F15/F$29) -> 0.027809923 | H15: ='Parameter & Regeln'!$B$37/'Parameter & Regeln'!$B$4 -> 0.017458778 | I15: =H15*F$29 -> 284.38865 | J15: =I15-F15 -> -168.61135 | K15: =G15-H15 -> 0.010351145 | L15: =IF(C15="Aktie",IF(K15>'Parameter & Regeln'!B$9,"📉 Reduzieren",IF(K15<-'Parameter & Regeln'!B$9,"📈 Aufstocken","⚖️ Halten")),IF(K15>'Parameter & Regeln'!B$8,"📉 Reduzieren",IF(K15<-'Parameter & Regeln'!B$8,"📈 Aufstocken","⚖️ Halten"))) -> ⚖️ Halten | M15: =IF(C15="Aktie",IF(G15>'Parameter & Regeln'!B$10,"🚨 ÜBER CAP","✅ OK"),"") -> ✅ OK | N15: DEFCON 3 (71) | Abel Käufe $15.3M | O15: ✅ Clean | P15: =IF(C15="Aktie",'Parameter & Regeln'!$B$4*'Parameter & Regeln'!$B$6*Q15/SUMIFS($Q$5:$Q$24,$C$5:$C$24,"Aktie"),IFERROR(VLOOKUP(B15,'Parameter & Regeln'!$A$56:$B$62,2,FALSE),0)) -> 31.195114 | Q15: =IF(OR(C15="ETF",C15="Gold"),H15,IF(C15<>"Aktie",0,IF(OR(LEFT(O15,1)="🔴",LEFT(N15,8)="DEFCON 1"),0,IF(LEFT(N15,8)="DEFCON 2",IFERROR(VLOOKUP(B15,'Parameter & Regeln'!$A$41:$C$53,3,FALSE),0)*'Parameter & Regeln'!$B$27,IFERROR(VLOOKUP(B15,'Parameter & Regeln'!$A$41:$C$53,3,FALSE),0))))) -> 18 | R15: =IF(AND(C15="Aktie",OR(LEFT(O15,1)="🔴",LEFT(N15,8)="DEFCON 1")),IF(J15>'Parameter & Regeln'!$B$65,"🚩 FLAG (gesperrt)",""),IF(J15>'Parameter & Regeln'!$B$65,"🛒 Nachkaufen",IF(J15<-'Parameter & Regeln'!$B$65,"⏸️ Über Ziel","")))
A16: Broadcom | B16: AVGO | C16: Aktie | D16: Scalable | E16: 1 | F16: 481 | G16: =IF(F$29=0,0,F16/F$29) -> 0.029528858 | H16: ='Parameter & Regeln'!$B$35/'Parameter & Regeln'!$B$4 -> 0.038797284 | I16: =H16*F$29 -> 631.97478 | J16: =I16-F16 -> 150.97478 | K16: =G16-H16 -> -0.009268426 | L16: =IF(C16="Aktie",IF(K16>'Parameter & Regeln'!B$9,"📉 Reduzieren",IF(K16<-'Parameter & Regeln'!B$9,"📈 Aufstocken","⚖️ Halten")),IF(K16>'Parameter & Regeln'!B$8,"📉 Reduzieren",IF(K16<-'Parameter & Regeln'!B$8,"📈 Aufstocken","⚖️ Halten"))) -> ⚖️ Halten | M16: =IF(C16="Aktie",IF(G16>'Parameter & Regeln'!B$10,"🚨 ÜBER CAP","✅ OK"),"") -> ✅ OK | N16: DEFCON 2 (56) | Q2 04.06. | O16: 🔴 FLAG: Insider-Selling 90d $106M+ | Aktiviert 27.04.2026 | Q2 FY26 Vollanalyse 04.06. Score 53→56 (D2, FLAG bleibt) | Re-Eval Q3 FY26 ~02.09. | P16: =IF(C16="Aktie",'Parameter & Regeln'!$B$4*'Parameter & Regeln'!$B$6*Q16/SUMIFS($Q$5:$Q$24,$C$5:$C$24,"Aktie"),IFERROR(VLOOKUP(B16,'Parameter & Regeln'!$A$56:$B$62,2,FALSE),0)) -> 0 | Q16: =IF(OR(C16="ETF",C16="Gold"),H16,IF(C16<>"Aktie",0,IF(OR(LEFT(O16,1)="🔴",LEFT(N16,8)="DEFCON 1"),0,IF(LEFT(N16,8)="DEFCON 2",IFERROR(VLOOKUP(B16,'Parameter & Regeln'!$A$41:$C$53,3,FALSE),0)*'Parameter & Regeln'!$B$27,IFERROR(VLOOKUP(B16,'Parameter & Regeln'!$A$41:$C$53,3,FALSE),0))))) -> 0 | R16: =IF(AND(C16="Aktie",OR(LEFT(O16,1)="🔴",LEFT(N16,8)="DEFCON 1")),IF(J16>'Parameter & Regeln'!$B$65,"🚩 FLAG (gesperrt)",""),IF(J16>'Parameter & Regeln'!$B$65,"🛒 Nachkaufen",IF(J16<-'Parameter & Regeln'!$B$65,"⏸️ Über Ziel","")))
A17: Hermès | B17: RMS | C17: Aktie | D17: Scalable | E17: 0 | F17: 432 | G17: =IF(F$29=0,0,F17/F$29) -> 0.026520721 | H17: ='Parameter & Regeln'!$B$37/'Parameter & Regeln'!$B$4 -> 0.017458778 | I17: =H17*F$29 -> 284.38865 | J17: =I17-F17 -> -147.61135 | K17: =G17-H17 -> 0.009061943 | L17: =IF(C17="Aktie",IF(K17>'Parameter & Regeln'!B$9,"📉 Reduzieren",IF(K17<-'Parameter & Regeln'!B$9,"📈 Aufstocken","⚖️ Halten")),IF(K17>'Parameter & Regeln'!B$8,"📉 Reduzieren",IF(K17<-'Parameter & Regeln'!B$8,"📈 Aufstocken","⚖️ Halten"))) -> ⚖️ Halten | M17: =IF(C17="Aktie",IF(G17>'Parameter & Regeln'!B$10,"🚨 ÜBER CAP","✅ OK"),"") -> ✅ OK | N17: DEFCON 3 (68) | Q1 Miss: −8.4% | Moat intakt | O17: ✅ Clean | Re-Analyse 17.04.2026 v3.7 | P17: =IF(C17="Aktie",'Parameter & Regeln'!$B$4*'Parameter & Regeln'!$B$6*Q17/SUMIFS($Q$5:$Q$24,$C$5:$C$24,"Aktie"),IFERROR(VLOOKUP(B17,'Parameter & Regeln'!$A$56:$B$62,2,FALSE),0)) -> 31.195114 | Q17: =IF(OR(C17="ETF",C17="Gold"),H17,IF(C17<>"Aktie",0,IF(OR(LEFT(O17,1)="🔴",LEFT(N17,8)="DEFCON 1"),0,IF(LEFT(N17,8)="DEFCON 2",IFERROR(VLOOKUP(B17,'Parameter & Regeln'!$A$41:$C$53,3,FALSE),0)*'Parameter & Regeln'!$B$27,IFERROR(VLOOKUP(B17,'Parameter & Regeln'!$A$41:$C$53,3,FALSE),0))))) -> 18 | R17: =IF(AND(C17="Aktie",OR(LEFT(O17,1)="🔴",LEFT(N17,8)="DEFCON 1")),IF(J17>'Parameter & Regeln'!$B$65,"🚩 FLAG (gesperrt)",""),IF(J17>'Parameter & Regeln'!$B$65,"🛒 Nachkaufen",IF(J17<-'Parameter & Regeln'!$B$65,"⏸️ Über Ziel","")))
A18: Keyence | B18: KYCCF | C18: Aktie | D18: Scalable | E18: 0 | F18: 0 | G18: =IF(F$29=0,0,F18/F$29) -> 0 | H18: ='Parameter & Regeln'!$B$36/'Parameter & Regeln'!$B$4 -> 0.031037827 | I18: =H18*F$29 -> 505.57983 | J18: =I18-F18 -> 505.57983 | K18: =G18-H18 -> -0.031037827 | L18: =IF(C18="Aktie",IF(K18>'Parameter & Regeln'!B$9,"📉 Reduzieren",IF(K18<-'Parameter & Regeln'!B$9,"📈 Aufstocken","⚖️ Halten")),IF(K18>'Parameter & Regeln'!B$8,"📉 Reduzieren",IF(K18<-'Parameter & Regeln'!B$8,"📈 Aufstocken","⚖️ Halten"))) -> ⚖️ Halten | M18: =IF(C18="Aktie",IF(G18>'Parameter & Regeln'!B$10,"🚨 ÜBER CAP","✅ OK"),"") -> ✅ OK | N18: DEFCON 3 (67) | O3 13.06. | O18: ✅ Clean | P18: =IF(C18="Aktie",'Parameter & Regeln'!$B$4*'Parameter & Regeln'!$B$6*Q18/SUMIFS($Q$5:$Q$24,$C$5:$C$24,"Aktie"),IFERROR(VLOOKUP(B18,'Parameter & Regeln'!$A$56:$B$62,2,FALSE),0)) -> 55.457981 | Q18: =IF(OR(C18="ETF",C18="Gold"),H18,IF(C18<>"Aktie",0,IF(OR(LEFT(O18,1)="🔴",LEFT(N18,8)="DEFCON 1"),0,IF(LEFT(N18,8)="DEFCON 2",IFERROR(VLOOKUP(B18,'Parameter & Regeln'!$A$41:$C$53,3,FALSE),0)*'Parameter & Regeln'!$B$27,IFERROR(VLOOKUP(B18,'Parameter & Regeln'!$A$41:$C$53,3,FALSE),0))))) -> 32 | R18: =IF(AND(C18="Aktie",OR(LEFT(O18,1)="🔴",LEFT(N18,8)="DEFCON 1")),IF(J18>'Parameter & Regeln'!$B$65,"🚩 FLAG (gesperrt)",""),IF(J18>'Parameter & Regeln'!$B$65,"🛒 Nachkaufen",IF(J18<-'Parameter & Regeln'!$B$65,"⏸️ Über Ziel",""))) -> 🛒 Nachkaufen
A19: Microsoft | B19: MSFT | C19: Aktie | D19: Scalable | E19: 1 | F19: 412 | G19: =IF(F$29=0,0,F19/F$29) -> 0.02529291 | H19: ='Parameter & Regeln'!$B$35/'Parameter & Regeln'!$B$4 -> 0.038797284 | I19: =H19*F$29 -> 631.97478 | J19: =I19-F19 -> 219.97478 | K19: =G19-H19 -> -0.013504374 | L19: =IF(C19="Aktie",IF(K19>'Parameter & Regeln'!B$9,"📉 Reduzieren",IF(K19<-'Parameter & Regeln'!B$9,"📈 Aufstocken","⚖️ Halten")),IF(K19>'Parameter & Regeln'!B$8,"📉 Reduzieren",IF(K19<-'Parameter & Regeln'!B$8,"📈 Aufstocken","⚖️ Halten"))) -> ⚖️ Halten | M19: =IF(C19="Aktie",IF(G19>'Parameter & Regeln'!B$10,"🚨 ÜBER CAP","✅ OK"),"") -> ✅ OK | N19: DEFCON 2 (50) | O19: 🔴 FLAG: CapEx/OCF aktiv | Score 50 | DEFCON 2 | Bull-Case Trigger B FAIL (CY26 $190B) | Re-Check Q4 FY26 ~Juli | P19: =IF(C19="Aktie",'Parameter & Regeln'!$B$4*'Parameter & Regeln'!$B$6*Q19/SUMIFS($Q$5:$Q$24,$C$5:$C$24,"Aktie"),IFERROR(VLOOKUP(B19,'Parameter & Regeln'!$A$56:$B$62,2,FALSE),0)) -> 0 | Q19: =IF(OR(C19="ETF",C19="Gold"),H19,IF(C19<>"Aktie",0,IF(OR(LEFT(O19,1)="🔴",LEFT(N19,8)="DEFCON 1"),0,IF(LEFT(N19,8)="DEFCON 2",IFERROR(VLOOKUP(B19,'Parameter & Regeln'!$A$41:$C$53,3,FALSE),0)*'Parameter & Regeln'!$B$27,IFERROR(VLOOKUP(B19,'Parameter & Regeln'!$A$41:$C$53,3,FALSE),0))))) -> 0 | R19: =IF(AND(C19="Aktie",OR(LEFT(O19,1)="🔴",LEFT(N19,8)="DEFCON 1")),IF(J19>'Parameter & Regeln'!$B$65,"🚩 FLAG (gesperrt)",""),IF(J19>'Parameter & Regeln'!$B$65,"🛒 Nachkaufen",IF(J19<-'Parameter & Regeln'!$B$65,"⏸️ Über Ziel","")))
A20: Schneider Electric | B20: SU | C20: Aktie | D20: Scalable | E20: 0 | F20: 420 | G20: =IF(F$29=0,0,F20/F$29) -> 0.025784034 | H20: ='Parameter & Regeln'!$B$37/'Parameter & Regeln'!$B$4 -> 0.017458778 | I20: =H20*F$29 -> 284.38865 | J20: =I20-F20 -> -135.61135 | K20: =G20-H20 -> 0.0083252563 | L20: =IF(C20="Aktie",IF(K20>'Parameter & Regeln'!B$9,"📉 Reduzieren",IF(K20<-'Parameter & Regeln'!B$9,"📈 Aufstocken","⚖️ Halten")),IF(K20>'Parameter & Regeln'!B$8,"📉 Reduzieren",IF(K20<-'Parameter & Regeln'!B$8,"📈 Aufstocken","⚖️ Halten"))) -> ⚖️ Halten | M20: =IF(C20="Aktie",IF(G20>'Parameter & Regeln'!B$10,"🚨 ÜBER CAP","✅ OK"),"") -> ✅ OK | N20: DEFCON 3 (69) | O20: ✅ Clean | P20: =IF(C20="Aktie",'Parameter & Regeln'!$B$4*'Parameter & Regeln'!$B$6*Q20/SUMIFS($Q$5:$Q$24,$C$5:$C$24,"Aktie"),IFERROR(VLOOKUP(B20,'Parameter & Regeln'!$A$56:$B$62,2,FALSE),0)) -> 31.195114 | Q20: =IF(OR(C20="ETF",C20="Gold"),H20,IF(C20<>"Aktie",0,IF(OR(LEFT(O20,1)="🔴",LEFT(N20,8)="DEFCON 1"),0,IF(LEFT(N20,8)="DEFCON 2",IFERROR(VLOOKUP(B20,'Parameter & Regeln'!$A$41:$C$53,3,FALSE),0)*'Parameter & Regeln'!$B$27,IFERROR(VLOOKUP(B20,'Parameter & Regeln'!$A$41:$C$53,3,FALSE),0))))) -> 18 | R20: =IF(AND(C20="Aktie",OR(LEFT(O20,1)="🔴",LEFT(N20,8)="DEFCON 1")),IF(J20>'Parameter & Regeln'!$B$65,"🚩 FLAG (gesperrt)",""),IF(J20>'Parameter & Regeln'!$B$65,"🛒 Nachkaufen",IF(J20<-'Parameter & Regeln'!$B$65,"⏸️ Über Ziel","")))
A21: ServiceNow | B21: NOW | C21: Aktie | D21: Scalable | E21: 1 | F21: 954 | G21: =IF(F$29=0,0,F21/F$29) -> 0.058566592 | H21: ='Parameter & Regeln'!$B$35/'Parameter & Regeln'!$B$4 -> 0.038797284 | I21: =H21*F$29 -> 631.97478 | J21: =I21-F21 -> -322.02522 | K21: =G21-H21 -> 0.019769308 | L21: =IF(C21="Aktie",IF(K21>'Parameter & Regeln'!B$9,"📉 Reduzieren",IF(K21<-'Parameter & Regeln'!B$9,"📈 Aufstocken","⚖️ Halten")),IF(K21>'Parameter & Regeln'!B$8,"📉 Reduzieren",IF(K21<-'Parameter & Regeln'!B$8,"📈 Aufstocken","⚖️ Halten"))) -> ⚖️ Halten | M21: =IF(C21="Aktie",IF(G21>'Parameter & Regeln'!B$10,"🚨 ÜBER CAP","✅ OK"),"") -> ✅ OK | N21: DEFCON 3 (–) | Neu 04.06. | O21: ✅ Clean | P21: =IF(C21="Aktie",'Parameter & Regeln'!$B$4*'Parameter & Regeln'!$B$6*Q21/SUMIFS($Q$5:$Q$24,$C$5:$C$24,"Aktie"),IFERROR(VLOOKUP(B21,'Parameter & Regeln'!$A$56:$B$62,2,FALSE),0)) -> 69.322476 | Q21: =IF(OR(C21="ETF",C21="Gold"),H21,IF(C21<>"Aktie",0,IF(OR(LEFT(O21,1)="🔴",LEFT(N21,8)="DEFCON 1"),0,IF(LEFT(N21,8)="DEFCON 2",IFERROR(VLOOKUP(B21,'Parameter & Regeln'!$A$41:$C$53,3,FALSE),0)*'Parameter & Regeln'!$B$27,IFERROR(VLOOKUP(B21,'Parameter & Regeln'!$A$41:$C$53,3,FALSE),0))))) -> 40 | R21: =IF(AND(C21="Aktie",OR(LEFT(O21,1)="🔴",LEFT(N21,8)="DEFCON 1")),IF(J21>'Parameter & Regeln'!$B$65,"🚩 FLAG (gesperrt)",""),IF(J21>'Parameter & Regeln'!$B$65,"🛒 Nachkaufen",IF(J21<-'Parameter & Regeln'!$B$65,"⏸️ Über Ziel",""))) -> ⏸️ Über Ziel
A22: Thermo Fisher | B22: TMO | C22: Aktie | D22: Scalable | E22: 1 | F22: 396 | G22: =IF(F$29=0,0,F22/F$29) -> 0.024310661 | H22: ='Parameter & Regeln'!$B$37/'Parameter & Regeln'!$B$4 -> 0.017458778 | I22: =H22*F$29 -> 284.38865 | J22: =I22-F22 -> -111.61135 | K22: =G22-H22 -> 0.0068518829 | L22: =IF(C22="Aktie",IF(K22>'Parameter & Regeln'!B$9,"📉 Reduzieren",IF(K22<-'Parameter & Regeln'!B$9,"📈 Aufstocken","⚖️ Halten")),IF(K22>'Parameter & Regeln'!B$8,"📉 Reduzieren",IF(K22<-'Parameter & Regeln'!B$8,"📈 Aufstocken","⚖️ Halten"))) -> ⚖️ Halten | M22: =IF(C22="Aktie",IF(G22>'Parameter & Regeln'!B$10,"🚨 ÜBER CAP","✅ OK"),"") -> ✅ OK | N22: DEFCON 3 (67) | O22: 🟡 DEFCON 3 (67) | fcf_trend_neg Resolve (Q1 WC-Unwind bestätigt) | Q2 ~Ende Juli | P22: =IF(C22="Aktie",'Parameter & Regeln'!$B$4*'Parameter & Regeln'!$B$6*Q22/SUMIFS($Q$5:$Q$24,$C$5:$C$24,"Aktie"),IFERROR(VLOOKUP(B22,'Parameter & Regeln'!$A$56:$B$62,2,FALSE),0)) -> 31.195114 | Q22: =IF(OR(C22="ETF",C22="Gold"),H22,IF(C22<>"Aktie",0,IF(OR(LEFT(O22,1)="🔴",LEFT(N22,8)="DEFCON 1"),0,IF(LEFT(N22,8)="DEFCON 2",IFERROR(VLOOKUP(B22,'Parameter & Regeln'!$A$41:$C$53,3,FALSE),0)*'Parameter & Regeln'!$B$27,IFERROR(VLOOKUP(B22,'Parameter & Regeln'!$A$41:$C$53,3,FALSE),0))))) -> 18 | R22: =IF(AND(C22="Aktie",OR(LEFT(O22,1)="🔴",LEFT(N22,8)="DEFCON 1")),IF(J22>'Parameter & Regeln'!$B$65,"🚩 FLAG (gesperrt)",""),IF(J22>'Parameter & Regeln'!$B$65,"🛒 Nachkaufen",IF(J22<-'Parameter & Regeln'!$B$65,"⏸️ Über Ziel","")))
A23: Visa | B23: V | C23: Aktie | D23: Scalable | E23: 1 | F23: 479 | G23: =IF(F$29=0,0,F23/F$29) -> 0.029406077 | H23: ='Parameter & Regeln'!$B$36/'Parameter & Regeln'!$B$4 -> 0.031037827 | I23: =H23*F$29 -> 505.57983 | J23: =I23-F23 -> 26.579825 | K23: =G23-H23 -> -0.0016317503 | L23: =IF(C23="Aktie",IF(K23>'Parameter & Regeln'!B$9,"📉 Reduzieren",IF(K23<-'Parameter & Regeln'!B$9,"📈 Aufstocken","⚖️ Halten")),IF(K23>'Parameter & Regeln'!B$8,"📉 Reduzieren",IF(K23<-'Parameter & Regeln'!B$8,"📈 Aufstocken","⚖️ Halten"))) -> ⚖️ Halten | M23: =IF(C23="Aktie",IF(G23>'Parameter & Regeln'!B$10,"🚨 ÜBER CAP","✅ OK"),"") -> ✅ OK | N23: DEFCON 2 (64) | O23: 🟠 DEFCON 2 (64) | Q2 Beat-Cascade D3 (mittags) → Codex-Review-Revert D2 (spätabends, HIGH-1+2 28.04.) | Q3 ~Ende Juli ROIC-Verify | P23: =IF(C23="Aktie",'Parameter & Regeln'!$B$4*'Parameter & Regeln'!$B$6*Q23/SUMIFS($Q$5:$Q$24,$C$5:$C$24,"Aktie"),IFERROR(VLOOKUP(B23,'Parameter & Regeln'!$A$56:$B$62,2,FALSE),0)) -> 27.72899 | Q23: =IF(OR(C23="ETF",C23="Gold"),H23,IF(C23<>"Aktie",0,IF(OR(LEFT(O23,1)="🔴",LEFT(N23,8)="DEFCON 1"),0,IF(LEFT(N23,8)="DEFCON 2",IFERROR(VLOOKUP(B23,'Parameter & Regeln'!$A$41:$C$53,3,FALSE),0)*'Parameter & Regeln'!$B$27,IFERROR(VLOOKUP(B23,'Parameter & Regeln'!$A$41:$C$53,3,FALSE),0))))) -> 16 | R23: =IF(AND(C23="Aktie",OR(LEFT(O23,1)="🔴",LEFT(N23,8)="DEFCON 1")),IF(J23>'Parameter & Regeln'!$B$65,"🚩 FLAG (gesperrt)",""),IF(J23>'Parameter & Regeln'!$B$65,"🛒 Nachkaufen",IF(J23<-'Parameter & Regeln'!$B$65,"⏸️ Über Ziel","")))
A24: Zeta Global | B24: ZETA | C24: Aktie | D24: Scalable | E24: 1 | F24: 428 | G24: =IF(F$29=0,0,F24/F$29) -> 0.026275159 | H24: ='Parameter & Regeln'!$B$37/'Parameter & Regeln'!$B$4 -> 0.017458778 | I24: =H24*F$29 -> 284.38865 | J24: =I24-F24 -> -143.61135 | K24: =G24-H24 -> 0.0088163807 | L24: =IF(C24="Aktie",IF(K24>'Parameter & Regeln'!B$9,"📉 Reduzieren",IF(K24<-'Parameter & Regeln'!B$9,"📈 Aufstocken","⚖️ Halten")),IF(K24>'Parameter & Regeln'!B$8,"📉 Reduzieren",IF(K24<-'Parameter & Regeln'!B$8,"📈 Aufstocken","⚖️ Halten"))) -> ⚖️ Halten | M24: =IF(C24="Aktie",IF(G24>'Parameter & Regeln'!B$10,"🚨 ÜBER CAP","✅ OK"),"") -> ✅ OK | N24: DEFCON 3 (–) | Neu 04.06. | O24: ✅ Clean | P24: =IF(C24="Aktie",'Parameter & Regeln'!$B$4*'Parameter & Regeln'!$B$6*Q24/SUMIFS($Q$5:$Q$24,$C$5:$C$24,"Aktie"),IFERROR(VLOOKUP(B24,'Parameter & Regeln'!$A$56:$B$62,2,FALSE),0)) -> 31.195114 | Q24: =IF(OR(C24="ETF",C24="Gold"),H24,IF(C24<>"Aktie",0,IF(OR(LEFT(O24,1)="🔴",LEFT(N24,8)="DEFCON 1"),0,IF(LEFT(N24,8)="DEFCON 2",IFERROR(VLOOKUP(B24,'Parameter & Regeln'!$A$41:$C$53,3,FALSE),0)*'Parameter & Regeln'!$B$27,IFERROR(VLOOKUP(B24,'Parameter & Regeln'!$A$41:$C$53,3,FALSE),0))))) -> 18 | R24: =IF(AND(C24="Aktie",OR(LEFT(O24,1)="🔴",LEFT(N24,8)="DEFCON 1")),IF(J24>'Parameter & Regeln'!$B$65,"🚩 FLAG (gesperrt)",""),IF(J24>'Parameter & Regeln'!$B$65,"🛒 Nachkaufen",IF(J24<-'Parameter & Regeln'!$B$65,"⏸️ Über Ziel","")))
A25: 📊 GESAMT | F25: =SUM(F5:F24) -> 15258.15 | G25: =SUM(G5:G24) -> 0.93670634 | H25: =SUM(H5:H24) -> 1 | I25: =SUM(I5:I24) -> 16289.15 | J25: =ROUND(SUM(J5:J24),2) -> 1031 | K25: {=SUMPRODUCT((C5:C24="Aktie")*ABS(K5:K24))/COUNTIF(C5:C24,"Aktie")} -> 0.011008732 | L25: Ø Drift Aktien | M25: =COUNTIF(M5:M24,"🚨 ÜBER CAP") -> 0 | N25: =COUNTIF(N5:N24,"DEFCON 1*")+COUNTIF(N5:N24,"DEFCON 2*")+COUNTIF(N5:N24,"DEFCON 3*") -> 13 | O25: =COUNTIF(O5:O24,"🚩*")+COUNTIF(O5:O24,"🔴*") -> 4 | P25: =SUMIF(C5:C24,"Aktie",P5:P24)+SUMIF(C5:C24,"<>Aktie",P5:P24) -> 1030.943
K26: {=SUMPRODUCT((C5:C24<>"Aktie")*ABS(K5:K24))/COUNTIF(C5:C24,"<>Aktie")} -> 0.034534434 | L26: Ø ETF/Gold-Drift | M26: =COUNTIF(M5:M11,"🚨 ÜBER CAP") -> 0 | N26: ⚠️ DEFCON ≤ 3 | O26: 🚩 Aktive FLAGs | P26: Check: Sparrate gesamt
A27: Scalable Cash (verfügbar) | F27: 74.3
A28: 📝 Neuinvestition (manuell eingeben) | F28: 1031
A29: Gesamtwert nach Invest | F29: =F25 + F28 -> 16289.15
A30: 💸 ING-Überweisung (Sparplan) | F30: =SUMIFS(P5:P24,D5:D24,"ING") -> 411
A31: 💰 Cash-Deckung Scalable-Anteil | F31: =IF((F28-F30)<=0,0,F27/(F28-F30)) -> 0.11983871
A33: ℹ️ LEGENDE – Spalten-Logik
A34: 💶 Sparrate (P) | B34: Automatischer Sparplan: ETF/Gold feste Raten, Aktien Tier-gewichtet (T1/T2/T3). FLAG/DEFCON überschreibt → 0 € bzw. 50% Sockel. Unabhängig vom Tageskurs.
A35: 📉 Fehlbetrag (J) | B35: Rebalancing-Signal: Ist vs. Ziel-Portfolio. Steuert NICHT den Sparplan, sondern dient manuellen Eingriffen (Einmalkäufe, Umschichtungen mit extra Cash).
A36: 🛒 Nachkauf-Signal (R) | B36: Schlägt an, wenn Fehlbetrag > Schwelle (Parameter B64, akt. 300 €): 🛒 Nachkaufen = stark unter Ziel · ⏸️ Über Ziel = ggf. pausieren · 🚩 FLAG (gesperrt) = unter Ziel, aber FLAG verhindert Nachkauf.

Sheet US-Exposure
A1: US-EXPOSURE TRACKER
A3: Position | B3: Ticker | C3: Depotwert € | D3: US-Faktor | E3: US-Anteil €
A4: ='Portfolio & Rebalancing'!A5 -> EUWAX Gold | B4: ='Portfolio & Rebalancing'!B5 -> EWG2 | C4: ='Portfolio & Rebalancing'!F5 -> 654 | D4: ='Portfolio & Rebalancing'!E5 -> 0 | E4: =C4*D4 -> 0
A5: ='Portfolio & Rebalancing'!A6 -> iShares Core MSCI World | B5: ='Portfolio & Rebalancing'!B6 -> IWDA | C5: ='Portfolio & Rebalancing'!F6 -> 3943.46 | D5: ='Portfolio & Rebalancing'!E6 -> 0.7 | E5: =C5*D5 -> 2760.422
A6: ='Portfolio & Rebalancing'!A7 -> iShares Core MSCI EM IMI | B6: ='Portfolio & Rebalancing'!B7 -> EIMI | C6: ='Portfolio & Rebalancing'!F7 -> 1349.52 | D6: ='Portfolio & Rebalancing'!E7 -> 0 | E6: =C6*D6 -> 0
A7: ='Portfolio & Rebalancing'!A8 -> Xtrackers MSCI World ex USA | B7: ='Portfolio & Rebalancing'!B8 -> EXUS | C7: ='Portfolio & Rebalancing'!F8 -> 1978.17 | D7: ='Portfolio & Rebalancing'!E8 -> 0 | E7: =C7*D7 -> 0
A8: ='Portfolio & Rebalancing'!A9 -> Avantis Global Small Cap Value | B8: ='Portfolio & Rebalancing'!B9 -> AVGC | C8: ='Portfolio & Rebalancing'!F9 -> 1366 | D8: ='Portfolio & Rebalancing'!E9 -> 0.67 | E8: =C8*D8 -> 915.22
A9: ='Portfolio & Rebalancing'!A10 -> VanEck Space Innovators | B9: ='Portfolio & Rebalancing'!B10 -> JEDI | C9: ='Portfolio & Rebalancing'!F10 -> 0 | D9: ='Portfolio & Rebalancing'!E10 -> 0.62 | E9: =C9*D9 -> 0
A10: ='Portfolio & Rebalancing'!A11 -> WisdomTree Quantum Computing | B10: ='Portfolio & Rebalancing'!B11 -> WQTM | C10: ='Portfolio & Rebalancing'!F11 -> 193 | D10: ='Portfolio & Rebalancing'!E11 -> 0.68 | E10: =C10*D10 -> 131.24
A11: ='Portfolio & Rebalancing'!A12 -> Amazon.com | B11: ='Portfolio & Rebalancing'!B12 -> AMZN | C11: ='Portfolio & Rebalancing'!F12 -> 381 | D11: ='Portfolio & Rebalancing'!E12 -> 1 | E11: =C11*D11 -> 381
A12: ='Portfolio & Rebalancing'!A13 -> Amphenol | B12: ='Portfolio & Rebalancing'!B13 -> APH | C12: ='Portfolio & Rebalancing'!F13 -> 378 | D12: ='Portfolio & Rebalancing'!E13 -> 1 | E12: =C12*D12 -> 378
A13: ='Portfolio & Rebalancing'!A14 -> ASML Holding | B13: ='Portfolio & Rebalancing'!B14 -> ASML | C13: ='Portfolio & Rebalancing'!F14 -> 560 | D13: ='Portfolio & Rebalancing'!E14 -> 0 | E13: =C13*D13 -> 0
A14: ='Portfolio & Rebalancing'!A15 -> Berkshire Hathaway | B14: ='Portfolio & Rebalancing'!B15 -> BRK.B | C14: ='Portfolio & Rebalancing'!F15 -> 453 | D14: ='Portfolio & Rebalancing'!E15 -> 1 | E14: =C14*D14 -> 453
A15: ='Portfolio & Rebalancing'!A16 -> Broadcom | B15: ='Portfolio & Rebalancing'!B16 -> AVGO | C15: ='Portfolio & Rebalancing'!F16 -> 481 | D15: ='Portfolio & Rebalancing'!E16 -> 1 | E15: =C15*D15 -> 481
... A23: ='Portfolio & Rebalancing'!A24 -> Zeta Global | B23: ='Portfolio & Rebalancing'!B24 -> ZETA | C23: ='Portfolio & Rebalancing'!F24 -> 428 | D23: ='Portfolio & Rebalancing'!E24 -> 1 | E23: =C23*D23 -> 428
A24: ="GESAMT" -> GESAMT | C24: ='Portfolio & Rebalancing'!F25 -> 15258.15 | E24: =SUM(E4:E23) -> 8168.882
A26: US-Anteil (Ist) | B26: =IF('Portfolio & Rebalancing'!F25=0,0,E24/'Portfolio & Rebalancing'!F25) -> 0.53537827
A27: US-Anteil (Ziel) | B27: =SUMPRODUCT('Portfolio & Rebalancing'!$E$5:$E$24,'Portfolio & Rebalancing'!$I$5:$I$24)/SUM('Portfolio & Rebalancing'!$I$5:$I$24) -> 0.52614937
A28: US-Hard-Cap | B28: ='Parameter & Regeln'!B11 -> 0.63
A29: Status (Ist) | B29: =IF(B26>B28,"⛔ ÜBER CAP","✅ OK") -> ✅ OK
A30: Status (Ziel) | B30: =IF(B27>B28,"⛔ ZIEL ÜBER CAP","✅ Ziel OK") -> ✅ Ziel OK

Sheet Parameter & Regeln
A1: ⚙️ REBALANCING PARAMETER
A3: Parameter | B3: Wert | C3: Einheit
A4: Sparrate monatlich | B4: 1031 | C4: €
A5: ETF-Core Zielanteil | B5: 0.597 | C5: %
A6: Satelliten Zielanteil | B6: 0.353 | C6: %
A7: Gold Zielanteil | B7: 0.05 | C7: %
A8: Drift-Toleranz ETF/Gold | B8: 0.015 | C8: %
A9: Drift-Toleranz Aktien | B9: 0.04 | C9: %
A10: Single-Stock-Cap | B10: 0.1 | C10: %
A11: US-Hard-Cap | B11: 0.63 | C11: %
A12: Max Aktien Slots | B12: 13
A13: Aktien-Slots belegt | B13: =COUNTIF('Portfolio & Rebalancing'!C5:C24,"Aktie") -> 13
A14: Gesamt Positionen belegt | B14: =COUNTIFS('Portfolio & Rebalancing'!A5:A24,"<>",'Portfolio & Rebalancing'!F5:F24,">0") -> 18
A15: Drift-Warnschwelle (Faktor × Toleranz → K rot) | B15: 3 | C15: ×
A16: Allokations-Check (Summe ETF+Sat+Gold) | B16: =B5+B6+B7 -> 1 | C16: %
A17: 📋 REBALANCING-REGELN
A19: Situation | B19: Bedeutung | C19: Aktion
A20: Abweichung negativ (rot) | B20: Untergewicht | C20: 📈 Sparrate erhöhen/starten
A21: Abweichung positiv (gelb) | B21: Übergewicht | C21: 📉 Sparrate stoppen/drosseln
A22: Innerhalb Toleranz (grün) | B22: Gleichgewicht | C22: ⚖️ Sparrate weiterführen
A23: NIEMALS durch Verkauf rebalancen | B23: Steuer-Bremse | C23: Nur Sparplan umleiten
A25: Satelliten-Budget / Monat | B25: =B4*B6 -> 363.943 | C25: €
A26: Aktive Aktien (DEFCON 3+, kein 🔴 FLAG) | B26: =COUNTIFS('Portfolio & Rebalancing'!C5:C24,"Aktie",'Portfolio & Rebalancing'!N5:N24,"DEFCON 4*",'Portfolio & Rebalancing'!O5:O24,"<>🔴*")+COUNTIFS('Portfolio & Rebalancing'!C5:C24,"Aktie",'Portfolio & Rebalancing'!N5:N24,"DEFCON 3*",'Portfolio & Rebalancing'!O5:O24,"<>🔴*") -> 8
A27: DEFCON-2-Sockelbetrag (% der vollen Rate) | B27: 0.5 | C27: %
A28: 📋 DEFCON-SPARRATEN-LOGIK
A29: DEFCON 4 oder 3 (kein 🔴 FLAG) | B29: Volle Sparrate (Gewicht 1.0) | C29: Budget ÷ Σ Gewichte × 1.0
A30: DEFCON 2 (kein 🔴 FLAG) | B30: 50% Sockelbetrag (Gewicht 0.5) | C30: Budget ÷ Σ Gewichte × 0.5 — Position halten
A31: DEFCON 1 (egal welcher FLAG) | B31: 0 € – eingefroren | C31: Exit-Kandidat — Auswechslung prüfen
A32: 🔴 FLAG (egal welcher DEFCON) | B32: 0 € – eingefroren | C32: 🔴 FLAG überschreibt jeden Score
A34: 🎯 TIER-SYSTEM (Satelliten-Gewichtung)
A35: Tier 1 – Gewicht/SOLL-Rate | B35: 40 | C35: AMZN · MSFT · NOW · AVGO
A36: Tier 2 – Gewicht/SOLL-Rate | B36: 32 | C36: V · KYCCF · ASML
A37: Tier 3 – Gewicht/SOLL-Rate | B37: 18 | C37: RMS · BRK.B · TMO · APH · SU · ZETA
A39: 🎯 TIER-ZUORDNUNG (Ticker → Tier-Faktor)
A40: Ticker | B40: Tier | C40: Faktor
A41: AMZN | B41: 1 | C41: =$B$35 -> 40
A42: MSFT | B42: 1 | C42: =$B$35 -> 40
A43: NOW | B43: 1 | C43: =$B$35 -> 40
A44: AVGO | B44: 1 | C44: =$B$35 -> 40
A45: V | B45: 2 | C45: =$B$36 -> 32
...
